<?xml version="1.0" encoding="utf-8"?>
<!-- This URDF was automatically created by SolidWorks to URDF Exporter! Originally created by Stephen Brawner (brawner@gmail.com) 
     Commit Version: 1.6.0-4-g7f85cfe  Build Version: 1.6.7995.38578
     For more information, please see http://wiki.ros.org/sw_urdf_exporter -->
<robot
  name="Assem1urdf">
  <link
    name="base">
    <inertial>
      <origin
        xyz="0.226742516162307 0.246392950005474 0.270048837854102"
        rpy="0 0 0" />
      <mass
        value="2.28414900607297" />
      <inertia
        ixx="0.0207642464984385"
        ixy="-0.00431383295093611"
        ixz="0.00498544928650138"
        iyy="0.0160873927901403"
        iyz="0.0078904791645818"
        izz="0.0145242458550222" />
    </inertial>
    <visual>
      <origin
        xyz="0 0 0"
        rpy="0 0 0" />
      <geometry>
        <mesh
          filename="package://Assem1urdf/meshes/base.STL" />
      </geometry>
      <material
        name="">
        <color
          rgba="0.647058823529412 0.619607843137255 0.588235294117647 1" />
      </material>
    </visual>
    <collision>
      <origin
        xyz="0 0 0"
        rpy="0 0 0" />
      <geometry>
        <mesh
          filename="package://Assem1urdf/meshes/base.STL" />
      </geometry>
    </collision>
  </link>
  <link
    name="arm">
    <inertial>
      <origin
        xyz="-0.117297262997389 0.0166454356579845 -2.20275996552777E-06"
        rpy="0 0 0" />
      <mass
        value="0.801595578723009" />
      <inertia
        ixx="0.00045979820543184"
        ixy="-8.65057875643035E-05"
        ixz="1.25228199657154E-07"
        iyy="0.0126256787872376"
        iyz="-1.28719385423907E-08"
        izz="0.0124547980745786" />
    </inertial>
    <visual>
      <origin
        xyz="0 0 0"
        rpy="0 0 0" />
      <geometry>
        <mesh
          filename="package://Assem1urdf/meshes/arm.STL" />
      </geometry>
      <material
        name="">
        <color
          rgba="0.792156862745098 0.819607843137255 0.933333333333333 1" />
      </material>
    </visual>
    <collision>
      <origin
        xyz="0 0 0"
        rpy="0 0 0" />
      <geometry>
        <mesh
          filename="package://Assem1urdf/meshes/arm.STL" />
      </geometry>
    </collision>
  </link>
  <joint
    name="arm"
    type="fixed">
    <origin
      xyz="0.2943 -0.20183 0.32415"
      rpy="0 1.4642 -2.1138" />
    <parent
      link="base" />
    <child
      link="arm" />
    <axis
      xyz="0 0 0" />
    <limit
      lower="-1.57"
      upper="1.57"
      effort="10"
      velocity="100" />
  </joint>
  <link
    name="elbow">
    <inertial>
      <origin
        xyz="0.0461665493874402 0.0384330708710939 0.03442531586515"
        rpy="0 0 0" />
      <mass
        value="10.0771572550788" />
      <inertia
        ixx="0.0517031148725114"
        ixy="-0.000944025635907299"
        ixz="-0.000636032270997993"
        iyy="0.0485783980224759"
        iyz="-0.00227813254776931"
        izz="0.0138484582615806" />
    </inertial>
    <visual>
      <origin
        xyz="0 0 0"
        rpy="0 0 0" />
      <geometry>
        <mesh
          filename="package://Assem1urdf/meshes/elbow.STL" />
      </geometry>
      <material
        name="">
        <color
          rgba="0.647058823529412 0.619607843137255 0.588235294117647 1" />
      </material>
    </visual>
    <collision>
      <origin
        xyz="0 0 0"
        rpy="0 0 0" />
      <geometry>
        <mesh
          filename="package://Assem1urdf/meshes/elbow.STL" />
      </geometry>
    </collision>
  </link>
  <joint
    name="elbow"
    type="revolute">
    <origin
      xyz="-0.3 0 0"
      rpy="2.9215 0 -1.5708" />
    <parent
      link="arm" />
    <child
      link="elbow" />
    <axis
      xyz="1 0 0" />
    <limit
      lower="0"
      upper="0"
      effort="0"
      velocity="0" />
  </joint>
  <link
    name="hand">
    <inertial>
      <origin
        xyz="2.540124444117E-09 6.30749752428272E-09 -0.04240439081037"
        rpy="0 0 0" />
      <mass
        value="0.589705735830938" />
      <inertia
        ixx="0.00202301430719847"
        ixy="3.67639996001539E-11"
        ixz="8.38881551571725E-11"
        iyy="0.00240194500297304"
        iyz="2.18585193443254E-10"
        izz="0.000729900566469361" />
    </inertial>
    <visual>
      <origin
        xyz="0 0 0"
        rpy="0 0 0" />
      <geometry>
        <mesh
          filename="package://Assem1urdf/meshes/hand.STL" />
      </geometry>
      <material
        name="">
        <color
          rgba="0.647058823529412 0.619607843137255 0.588235294117647 1" />
      </material>
    </visual>
    <collision>
      <origin
        xyz="0 0 0"
        rpy="0 0 0" />
      <geometry>
        <mesh
          filename="package://Assem1urdf/meshes/hand.STL" />
      </geometry>
    </collision>
  </link>
  <joint
    name="hand"
    type="continuous">
    <origin
      xyz="0.048 0.045 0.25708"
      rpy="3.1416 0 -3.0994" />
    <parent
      link="elbow" />
    <child
      link="hand" />
    <axis
      xyz="0 0 1" />
  </joint>
  <link
    name="joint">
    <inertial>
      <origin
        xyz="0.0162559261217818 1.11022302462516E-16 2.22044604925031E-16"
        rpy="0 0 0" />
      <mass
        value="0.0782775952404967" />
      <inertia
        ixx="2.25342036343016E-05"
        ixy="-2.5410988417629E-20"
        ixz="2.20228566286118E-20"
        iyy="3.84769820900075E-05"
        iyz="1.18584612615602E-20"
        izz="4.51210465186549E-05" />
    </inertial>
    <visual>
      <origin
        xyz="0 0 0"
        rpy="0 0 0" />
      <geometry>
        <mesh
          filename="package://Assem1urdf/meshes/joint.STL" />
      </geometry>
      <material
        name="">
        <color
          rgba="0.792156862745098 0.819607843137255 0.933333333333333 1" />
      </material>
    </visual>
    <collision>
      <origin
        xyz="0 0 0"
        rpy="0 0 0" />
      <geometry>
        <mesh
          filename="package://Assem1urdf/meshes/joint.STL" />
      </geometry>
    </collision>
  </link>
  <joint
    name="joint"
    type="continuous">
    <origin
      xyz="0 0 -0.10192"
      rpy="1.5708 0.54061 -1.5708" />
    <parent
      link="hand" />
    <child
      link="joint" />
    <axis
      xyz="0 0 1" />
  </joint>
  <link
    name="claw1">
    <inertial>
      <origin
        xyz="0.0206522124406976 5.55111512312578E-17 0.0596136661385636"
        rpy="0 0 0" />
      <mass
        value="0.0230303728152378" />
      <inertia
        ixx="2.68926576922532E-05"
        ixy="2.37169225231204E-20"
        ixz="-7.06523506550488E-06"
        iyy="2.94324985028668E-05"
        iyz="9.25383494875323E-20"
        izz="3.09256975817937E-06" />
    </inertial>
    <visual>
      <origin
        xyz="0 0 0"
        rpy="0 0 0" />
      <geometry>
        <mesh
          filename="package://Assem1urdf/meshes/claw1.STL" />
      </geometry>
      <material
        name="">
        <color
          rgba="0.501960784313725 0 0 1" />
      </material>
    </visual>
    <collision>
      <origin
        xyz="0 0 0"
        rpy="0 0 0" />
      <geometry>
        <mesh
          filename="package://Assem1urdf/meshes/claw1.STL" />
      </geometry>
    </collision>
  </link>
  <joint
    name="claw1"
    type="continuous">
    <origin
      xyz="0.047 -0.035 0"
      rpy="-1.5708 0 -1.1062" />
    <parent
      link="joint" />
    <child
      link="claw1" />
    <axis
      xyz="0 1 0" />
  </joint>
</robot>