<sdf version='1.11'>
  <model name='leg1'>
    <link name='base_link'>
      <inertial>
        <pose>-0.00055856856062800784 0.12100156940500099 0.002499999999999997 0 0 0</pose>
        <mass>0.017892844407040882</mass>
        <inertia>
          <ixx>6.0000000000000002e-06</ixx>
          <ixy>0</ixy>
          <ixz>0</ixz>
          <iyy>5.0000000000000004e-06</iyy>
          <iyz>0</iyz>
          <izz>1.0000000000000001e-05</izz>
        </inertia>
      </inertial>
      <collision name='base_link_collision'>
        <pose>0 0 0 0 0 0</pose>
        <geometry>
          <mesh>
            <scale>0.001 0.001 0.001</scale>
            <uri>file:///home/houndsito/vt-cro/robogamescode/leg1_ws/install/leg1_description/share/leg1_description/meshes/base_link.stl</uri>
          </mesh>
        </geometry>
        <surface>
          <contact>
            <ode/>
          </contact>
          <friction>
            <ode>
              <mu>0.20000000000000001</mu>
              <mu2>0.20000000000000001</mu2>
            </ode>
          </friction>
        </surface>
      </collision>
      <visual name='base_link_visual'>
        <pose>0 0 0 0 0 0</pose>
        <geometry>
          <mesh>
            <scale>0.001 0.001 0.001</scale>
            <uri>file:///home/houndsito/vt-cro/robogamescode/leg1_ws/install/leg1_description/share/leg1_description/meshes/base_link.stl</uri>
          </mesh>
        </geometry>
        <material>
          <script>
            <name>Gazebo/Silver</name>
            <uri>file://media/materials/scripts/gazebo.material</uri>
          </script>
          <diffuse>0.875 0.875 0.875 1</diffuse>
          <ambient>0.875 0.875 0.875 1</ambient>
        </material>
      </visual>
      <self_collide>true</self_collide>
      <gravity>true</gravity>
    </link>
    <joint name='Revolute 8' type='revolute'>
      <pose relative_to='base_link'>0 0.089999999999999997 0.0050000000000000001 0 0 0</pose>
      <parent>base_link</parent>
      <child>upperleg_1</child>
      <axis>
        <xyz>0 0 1</xyz>
        <limit>
          <lower>-0.33161299999999999</lower>
          <upper>0.47123900000000002</upper>
          <effort>100</effort>
          <velocity>100</velocity>
        </limit>
        <dynamics>
          <spring_reference>0</spring_reference>
          <spring_stiffness>0</spring_stiffness>
        </dynamics>
      </axis>
    </joint>
    <link name='upperleg_1'>
      <pose relative_to='Revolute 8'>0 0 0 0 0 0</pose>
      <inertial>
        <pose>-0.075391165480534109 0 0.0048999999999999972 0 0 0</pose>
        <mass>0.039498804019950789</mass>
        <inertia>
          <ixx>1.9999999999999999e-06</ixx>
          <ixy>0</ixy>
          <ixz>0</ixz>
          <iyy>9.1000000000000003e-05</iyy>
          <iyz>0</iyz>
          <izz>9.2999999999999997e-05</izz>
        </inertia>
      </inertial>
      <collision name='upperleg_1_collision'>
        <pose>0 -0.089999999999999997 -0.0050000000000000001 0 0 0</pose>
        <geometry>
          <mesh>
            <scale>0.001 0.001 0.001</scale>
            <uri>file:///home/houndsito/vt-cro/robogamescode/leg1_ws/install/leg1_description/share/leg1_description/meshes/upperleg_1.stl</uri>
          </mesh>
        </geometry>
        <surface>
          <contact>
            <ode/>
          </contact>
          <friction>
            <ode>
              <mu>0.20000000000000001</mu>
              <mu2>0.20000000000000001</mu2>
            </ode>
          </friction>
        </surface>
      </collision>
      <visual name='upperleg_1_visual'>
        <pose>0 -0.089999999999999997 -0.0050000000000000001 0 0 0</pose>
        <geometry>
          <mesh>
            <scale>0.001 0.001 0.001</scale>
            <uri>file:///home/houndsito/vt-cro/robogamescode/leg1_ws/install/leg1_description/share/leg1_description/meshes/upperleg_1.stl</uri>
          </mesh>
        </geometry>
        <material>
          <script>
            <name>Gazebo/Silver</name>
            <uri>file://media/materials/scripts/gazebo.material</uri>
          </script>
          <diffuse>0.875 0.875 0.875 1</diffuse>
          <ambient>0.875 0.875 0.875 1</ambient>
        </material>
      </visual>
      <self_collide>true</self_collide>
    </link>
    <joint name='Revolute 14' type='revolute'>
      <pose relative_to='upperleg_1'>-0.14999999999999999 0 0 0 0 0</pose>
      <parent>upperleg_1</parent>
      <child>lowerleg_1</child>
      <axis>
        <xyz>0 0 1</xyz>
        <limit>
          <lower>-0.50614499999999996</lower>
          <upper>0.19198599999999999</upper>
          <effort>100</effort>
          <velocity>100</velocity>
        </limit>
        <dynamics>
          <spring_reference>0</spring_reference>
          <spring_stiffness>0</spring_stiffness>
        </dynamics>
      </axis>
    </joint>
    <link name='lowerleg_1'>
      <pose relative_to='Revolute 14'>0 0 0 0 0 0</pose>
      <inertial>
        <pose>-0.00048487497129850261 -0.074435144985854448 0.0062462445415356286 0 0 0</pose>
        <mass>0.032237031801720467</mass>
        <inertia>
          <ixx>3.2886518710689083e-05</ixx>
          <ixy>1.2233249213218341e-06</ixy>
          <ixz>-4.3468382630126509e-11</ixz>
          <iyy>2.0056126606852061e-06</iyy>
          <iyz>1.7296886466779271e-09</iyz>
          <izz>3.2892130698034558e-05</izz>
        </inertia>
      </inertial>
      <collision name='lowerleg_1_collision'>
        <pose>0.14999999999999999 -0.089999999999999997 -0.0050000000000000001 0 0 0</pose>
        <geometry>
          <mesh>
            <scale>0.001 0.001 0.001</scale>
            <uri>file:///home/houndsito/vt-cro/robogamescode/leg1_ws/install/leg1_description/share/leg1_description/meshes/lowerleg_1.stl</uri>
          </mesh>
        </geometry>
        <surface>
          <contact>
            <ode/>
          </contact>
          <friction>
            <ode>
              <mu>0.20000000000000001</mu>
              <mu2>0.20000000000000001</mu2>
            </ode>
          </friction>
        </surface>
      </collision>
      <collision name='lowerleg_1_fixed_joint_lump__sphere_1_collision_1'>
        <pose>0.14999999999999999 -0.089999999999999997 -0.0049999999999999992 0 0 0</pose>
        <geometry>
          <mesh>
            <scale>0.001 0.001 0.001</scale>
            <uri>file:///home/houndsito/vt-cro/robogamescode/leg1_ws/install/leg1_description/share/leg1_description/meshes/sphere_1.stl</uri>
          </mesh>
        </geometry>
        <surface>
          <contact>
            <ode/>
          </contact>
          <friction>
            <ode>
              <mu>0.20000000000000001</mu>
              <mu2>0.20000000000000001</mu2>
            </ode>
          </friction>
        </surface>
      </collision>
      <visual name='lowerleg_1_visual'>
        <pose>0.14999999999999999 -0.089999999999999997 -0.0050000000000000001 0 0 0</pose>
        <geometry>
          <mesh>
            <scale>0.001 0.001 0.001</scale>
            <uri>file:///home/houndsito/vt-cro/robogamescode/leg1_ws/install/leg1_description/share/leg1_description/meshes/lowerleg_1.stl</uri>
          </mesh>
        </geometry>
        <material>
          <script>
            <name>Gazebo/Silver</name>
            <uri>file://media/materials/scripts/gazebo.material</uri>
          </script>
          <diffuse>0.875 0.875 0.875 1</diffuse>
          <ambient>0.875 0.875 0.875 1</ambient>
        </material>
      </visual>
      <visual name='lowerleg_1_fixed_joint_lump__sphere_1_visual_1'>
        <pose>0.14999999999999999 -0.089999999999999997 -0.0049999999999999992 0 0 0</pose>
        <geometry>
          <mesh>
            <scale>0.001 0.001 0.001</scale>
            <uri>file:///home/houndsito/vt-cro/robogamescode/leg1_ws/install/leg1_description/share/leg1_description/meshes/sphere_1.stl</uri>
          </mesh>
        </geometry>
        <material>
          <script>
            <name>Gazebo/Silver</name>
            <uri>file://media/materials/scripts/gazebo.material</uri>
          </script>
          <diffuse>0.875 0.875 0.875 1</diffuse>
          <ambient>0.875 0.875 0.875 1</ambient>
        </material>
      </visual>
      <self_collide>true</self_collide>
      <self_collide>true</self_collide>
      <self_collide>true</self_collide>
    </link>
    <plugin name='control' filename='libgazebo_ros_control.so'/>
    <frame name='Rigid 13' attached_to='lowerleg_1'>
      <pose>-0.0025000000000000001 -0.075499999999999998 0.0087500000000000008 0 0 0</pose>
    </frame>
    <frame name='sphere_1' attached_to='Rigid 13'>
      <pose>0 0 0 0 0 0</pose>
    </frame>
  </model>
</sdf>
