<?xml version="1.0" ?>
<!-- =================================================================================== -->
<!-- |    This document was autogenerated by xacro from ./src/leg/leg1_description/urdf/leg1.xacro | -->
<!-- |    EDITING THIS FILE BY HAND IS NOT RECOMMENDED                                 | -->
<!-- =================================================================================== -->
<robot name="leg1">
  <material name="silver">
    <color rgba="0.700 0.700 0.700 1.000"/>
  </material>
  <transmission name="Revolute 8_tran">
    <type>transmission_interface/SimpleTransmission</type>
    <joint name="Revolute 8">
      <hardwareInterface>hardware_interface/EffortJointInterface</hardwareInterface>
    </joint>
    <actuator name="Revolute 8_actr">
      <hardwareInterface>hardware_interface/EffortJointInterface</hardwareInterface>
      <mechanicalReduction>1</mechanicalReduction>
    </actuator>
  </transmission>
  <transmission name="Revolute 9_tran">
    <type>transmission_interface/SimpleTransmission</type>
    <joint name="Revolute 9">
      <hardwareInterface>hardware_interface/EffortJointInterface</hardwareInterface>
    </joint>
    <actuator name="Revolute 9_actr">
      <hardwareInterface>hardware_interface/EffortJointInterface</hardwareInterface>
      <mechanicalReduction>1</mechanicalReduction>
    </actuator>
  </transmission>
  <transmission name="Revolute 10_tran">
    <type>transmission_interface/SimpleTransmission</type>
    <joint name="Revolute 10">
      <hardwareInterface>hardware_interface/EffortJointInterface</hardwareInterface>
    </joint>
    <actuator name="Revolute 10_actr">
      <hardwareInterface>hardware_interface/EffortJointInterface</hardwareInterface>
      <mechanicalReduction>1</mechanicalReduction>
    </actuator>
  </transmission>
  <transmission name="Revolute 14_tran">
    <type>transmission_interface/SimpleTransmission</type>
    <joint name="Revolute 14">
      <hardwareInterface>hardware_interface/EffortJointInterface</hardwareInterface>
    </joint>
    <actuator name="Revolute 14_actr">
      <hardwareInterface>hardware_interface/EffortJointInterface</hardwareInterface>
      <mechanicalReduction>1</mechanicalReduction>
    </actuator>
  </transmission>
  <gazebo>
    <plugin filename="libgazebo_ros_control.so" name="control"/>
  </gazebo>
  <gazebo reference="base_link">
    <material>Gazebo/Silver</material>
    <mu1>0.2</mu1>
    <mu2>0.2</mu2>
    <self_collide>true</self_collide>
    <gravity>true</gravity>
  </gazebo>
  <gazebo reference="upperleg_1">
    <material>Gazebo/Silver</material>
    <mu1>0.2</mu1>
    <mu2>0.2</mu2>
    <self_collide>true</self_collide>
  </gazebo>
  <gazebo reference="driveleg_1">
    <material>Gazebo/Silver</material>
    <mu1>0.2</mu1>
    <mu2>0.2</mu2>
    <self_collide>true</self_collide>
  </gazebo>
  <gazebo reference="lowerleg_1">
    <material>Gazebo/Silver</material>
    <mu1>0.2</mu1>
    <mu2>0.2</mu2>
    <self_collide>true</self_collide>
  </gazebo>
  <gazebo reference="sphere_1">
    <material>Gazebo/Silver</material>
    <mu1>0.2</mu1>
    <mu2>0.2</mu2>
    <self_collide>true</self_collide>
  </gazebo>
  <gazebo reference="lowerleg_1">
    <material>Gazebo/Silver</material>
    <mu1>0.2</mu1>
    <mu2>0.2</mu2>
    <self_collide>true</self_collide>
  </gazebo>
  <!-- //////////////////////// lINKS SECTION //////////////////////////////////////-->
  <link name="base_link">
    <inertial>
      <origin rpy="0 0 0" xyz="-0.0005585685606280078 0.12100156940500095 0.0024999999999999974"/>
      <mass value="0.01789284440704088"/>
      <inertia ixx="6e-06" ixy="-0.0" ixz="0.0" iyy="5e-06" iyz="-0.0" izz="1e-05"/>
    </inertial>
    <visual>
      <origin rpy="0 0 0" xyz="0 0 0"/>
      <geometry>
        <mesh filename="file:///home/houndsito/leg1_ws/install/leg1_description/share/leg1_description/meshes/base_link.stl" scale="0.001 0.001 0.001"/>
      </geometry>
      <material name="silver"/>
    </visual>
    <collision>
      <origin rpy="0 0 0" xyz="0 0 0"/>
      <geometry>
        <mesh filename="file:///home/houndsito/leg1_ws/install/leg1_description/share/leg1_description/meshes/base_link.stl" scale="0.001 0.001 0.001"/>
      </geometry>
    </collision>
  </link>
  <link name="upperleg_1">
    <inertial>
      <origin rpy="0 0 0" xyz="-0.07539116548053411 0.0 0.004899999999999997"/>
      <mass value="0.03949880401995079"/>
      <inertia ixx="2e-06" ixy="0.0" ixz="-0.0" iyy="9.1e-05" iyz="0.0" izz="9.3e-05"/>
    </inertial>
    <visual>
      <origin rpy="0 0 0" xyz="0.0 -0.09 -0.005"/>
      <geometry>
        <mesh filename="file:///home/houndsito/leg1_ws/install/leg1_description/share/leg1_description/meshes/upperleg_1.stl" scale="0.001 0.001 0.001"/>
      </geometry>
      <material name="silver"/>
    </visual>
    <collision>
      <origin rpy="0 0 0" xyz="0.0 -0.09 -0.005"/>
      <geometry>
        <mesh filename="file:///home/houndsito/leg1_ws/install/leg1_description/share/leg1_description/meshes/upperleg_1.stl" scale="0.001 0.001 0.001"/>
      </geometry>
    </collision>
  </link>
  <link name="driveleg_1">
    <inertial>
      <origin rpy="0 0 0" xyz="-0.05976865106430535 0.005429114943386826 0.004895930218958272"/>
      <mass value="0.023446265816511214"/>
      <inertia ixx="2.5e-06" ixy="0" ixz="0" iyy="5.0e-05" iyz="0" izz="5.2e-05"/>
    </inertial>
    <visual>
      <origin rpy="0 0 0" xyz="0.03048 -0.129263 -0.005"/>
      <geometry>
        <mesh filename="file:///home/houndsito/leg1_ws/install/leg1_description/share/leg1_description/meshes/driveleg_1.stl" scale="0.001 0.001 0.001"/>
      </geometry>
      <material name="silver"/>
    </visual>
    <collision>
      <origin rpy="0 0 0" xyz="0.03048 -0.129263 -0.005"/>
      <geometry>
        <mesh filename="file:///home/houndsito/leg1_ws/install/leg1_description/share/leg1_description/meshes/driveleg_1.stl" scale="0.001 0.001 0.001"/>
      </geometry>
    </collision>
  </link>
  

Virtual Link to break kinematic loop

  <link name="lowerleg_virtual">
    <inertial>
      <origin rpy="0 0 0" xyz="0.15 -0.14 -0.005"/>
      <mass value="0.001"/>
      <inertia ixx="1e-06" ixy="0.0" ixz="0.0" iyy="1e-06" iyz="0.0" izz="1e-06"/>
    </inertial>
  </link>
  <link name="lowerleg_1">
    <inertial>
      <origin rpy="0 0 0" xyz="-0.0008439272273708387 -0.060147780853207225 0.006243463622114645"/>
      <mass value="0.018521660836523925"/>
      <inertia ixx="2.3e-05" ixy="1e-06" ixz="0.0" iyy="1e-06" iyz="-0.0" izz="2.3e-05"/>
    </inertial>
    <visual>
      <origin rpy="0 0 0" xyz="0.15 -0.14 -0.005"/>
      <geometry>
        <mesh filename="file:///home/houndsito/leg1_ws/install/leg1_description/share/leg1_description/meshes/lowerleg_1.stl" scale="0.001 0.001 0.001"/>
      </geometry>
      <material name="silver"/>
    </visual>
    <collision>
      <origin rpy="0 0 0" xyz="0.15 -0.14 -0.005"/>
      <geometry>
        <mesh filename="file:///home/houndsito/leg1_ws/install/leg1_description/share/leg1_description/meshes/lowerleg_1.stl" scale="0.001 0.001 0.001"/>
      </geometry>
    </collision>
  </link>
  <link name="sphere_1">
    <inertial>
      <origin rpy="0 0 0" xyz="0.002500000292114779 -0.01822924307363568 -0.0025000000189316137"/>
      <mass value="0.013715370965196549"/>
      <inertia ixx="1e-06" ixy="-0.0" ixz="0.0" iyy="1e-06" iyz="0.0" izz="1e-06"/>
    </inertial>
    <visual>
      <origin rpy="0 0 0" xyz="0.1525 -0.0145 -0.01375"/>
      <geometry>
        <mesh filename="file:///home/houndsito/leg1_ws/install/leg1_description/share/leg1_description/meshes/sphere_1.stl" scale="0.001 0.001 0.001"/>
      </geometry>
      <material name="silver"/>
    </visual>
    <collision>
      <origin rpy="0 0 0" xyz="0.1525 -0.0145 -0.01375"/>
      <geometry>
        <mesh filename="file:///home/houndsito/leg1_ws/install/leg1_description/share/leg1_description/meshes/sphere_1.stl" scale="0.001 0.001 0.001"/>
      </geometry>
    </collision>
  </link>
  <!-- //////////////////////// JOINTS SECTION //////////////////////////////////////-->
  <joint name="Revolute 8" type="revolute">
    <origin rpy="0 0 0" xyz="0.0 0.09 0.005"/>
    <parent link="base_link"/>
    <child link="upperleg_1"/>
    <axis xyz="0.0 0.0 1.0"/>
    <limit effort="100" lower="-0.331613" upper="0.471239" velocity="100"/>
  </joint>
  <joint name="Revolute 9" type="revolute">
    <origin rpy="0 0 0" xyz="-0.03048 0.129263 0.005"/>
    <parent link="base_link"/>
    <child link="driveleg_1"/>
    <axis xyz="0.0 0.0 -1.0"/>
    <limit effort="100" lower="-0.541052" upper="0.488692" velocity="100"/>
  </joint>
  <joint name="Revolute_10" type="revolute">
    <origin rpy="0 0 0" xyz="-0.11952 0.011 0.0"/>
    <parent link="driveleg_1"/>
    <child link="lowerleg_1"/>
    <axis xyz="0.0 0.0 1.0"/>
    <limit effort="100" lower="0.0004346" upper="1.2464" velocity="100"/>
  </joint>
  

Mimic_lowerleg Joint

  <joint name="mimic_lowerleg" type="revolute">
    <origin rpy="0 0 0" xyz="-0.15 0.0 0.0"/>
    <parent link="upperleg_1"/>
    <child link="lowerleg_virtual"/>
    <axis xyz="0.0 0.0 1.0"/>
    <limit effort="100" lower="0.0004346" upper="1.2464" velocity="100"/>
    <mimic joint="Revolute_10" multiplier="1.0" offset="0"/>
  </joint>
  <joint name="Rigid 14" type="revolute">
    <origin rpy="0 0 0" xyz="-0.11952 0.011 0.0"/>
    <parent link="lowerleg_virtual"/>
    <child link="lowerleg_1"/>
    <axis xyz="0.0 0.0 1.0"/>
    <limit effort="100" lower="0.0004346" upper="1.2464" velocity="100"/>
  </joint>
  <joint name="Rigid 13" type="fixed">
    <origin rpy="0 0 0" xyz="-0.0025 -0.1255 0.00875"/>
    <parent link="lowerleg_1"/>
    <child link="sphere_1"/>
  </joint>
</robot>
