<sdf version='1.11'>
  <model name='leg1'>
    <link name='base_link'>
      <inertial>
        <pose>-0.00055856856062800784 0.12100156940500099 0.002499999999999997 0 0 0</pose>
        <mass>0.017892844407040882</mass>
        <inertia>
          <ixx>6.0000000000000002e-06</ixx>
          <ixy>0</ixy>
          <ixz>0</ixz>
          <iyy>5.0000000000000004e-06</iyy>
          <iyz>0</iyz>
          <izz>1.0000000000000001e-05</izz>
        </inertia>
      </inertial>
      <collision name='base_link_collision'>
        <pose>0 0 0 0 0 0</pose>
        <geometry>
          <mesh>
            <scale>0.001 0.001 0.001</scale>
            <uri>file:///home/houndsito/leg1_ws/install/leg1_description/share/leg1_description/meshes/base_link.stl</uri>
          </mesh>
        </geometry>
        <surface>
          <contact>
            <ode/>
          </contact>
          <friction>
            <ode>
              <mu>0.20000000000000001</mu>
              <mu2>0.20000000000000001</mu2>
            </ode>
          </friction>
        </surface>
      </collision>
      <visual name='base_link_visual'>
        <pose>0 0 0 0 0 0</pose>
        <geometry>
          <mesh>
            <scale>0.001 0.001 0.001</scale>
            <uri>file:///home/houndsito/leg1_ws/install/leg1_description/share/leg1_description/meshes/base_link.stl</uri>
          </mesh>
        </geometry>
        <material>
          <script>
            <name>Gazebo/Silver</name>
            <uri>file://media/materials/scripts/gazebo.material</uri>
          </script>
          <diffuse>0.875 0.875 0.875 1</diffuse>
          <ambient>0.875 0.875 0.875 1</ambient>
        </material>
      </visual>
      <self_collide>true</self_collide>
      <gravity>true</gravity>
    </link>
    <joint name='Revolute 8' type='revolute'>
      <pose relative_to='base_link'>0 0.089999999999999997 0.0050000000000000001 0 0 0</pose>
      <parent>base_link</parent>
      <child>upperleg_1</child>
      <axis>
        <xyz>0 0 1</xyz>
        <limit>
          <lower>-0.33161299999999999</lower>
          <upper>0.47123900000000002</upper>
          <effort>100</effort>
          <velocity>100</velocity>
        </limit>
        <dynamics>
          <spring_reference>0</spring_reference>
          <spring_stiffness>0</spring_stiffness>
        </dynamics>
      </axis>
    </joint>
    <link name='upperleg_1'>
      <pose relative_to='Revolute 8'>0 0 0 0 0 0</pose>
      <inertial>
        <pose>-0.075391165480534109 0 0.0048999999999999972 0 0 0</pose>
        <mass>0.039498804019950789</mass>
        <inertia>
          <ixx>1.9999999999999999e-06</ixx>
          <ixy>0</ixy>
          <ixz>0</ixz>
          <iyy>9.1000000000000003e-05</iyy>
          <iyz>0</iyz>
          <izz>9.2999999999999997e-05</izz>
        </inertia>
      </inertial>
      <collision name='upperleg_1_collision'>
        <pose>0 -0.089999999999999997 -0.0050000000000000001 0 0 0</pose>
        <geometry>
          <mesh>
            <scale>0.001 0.001 0.001</scale>
            <uri>file:///home/houndsito/leg1_ws/install/leg1_description/share/leg1_description/meshes/upperleg_1.stl</uri>
          </mesh>
        </geometry>
        <surface>
          <contact>
            <ode/>
          </contact>
          <friction>
            <ode>
              <mu>0.20000000000000001</mu>
              <mu2>0.20000000000000001</mu2>
            </ode>
          </friction>
        </surface>
      </collision>
      <visual name='upperleg_1_visual'>
        <pose>0 -0.089999999999999997 -0.0050000000000000001 0 0 0</pose>
        <geometry>
          <mesh>
            <scale>0.001 0.001 0.001</scale>
            <uri>file:///home/houndsito/leg1_ws/install/leg1_description/share/leg1_description/meshes/upperleg_1.stl</uri>
          </mesh>
        </geometry>
        <material>
          <script>
            <name>Gazebo/Silver</name>
            <uri>file://media/materials/scripts/gazebo.material</uri>
          </script>
          <diffuse>0.875 0.875 0.875 1</diffuse>
          <ambient>0.875 0.875 0.875 1</ambient>
        </material>
      </visual>
      <self_collide>true</self_collide>
    </link>
    <joint name='mimic_lowerleg' type='revolute'>
      <pose relative_to='upperleg_1'>-0.14999999999999999 0 0 0 0 0</pose>
      <parent>upperleg_1</parent>
      <child>lowerleg_virtual</child>
      <axis>
        <xyz>0 0 1</xyz>
        <mimic joint='Revolute_10'>
          <multiplier>1</multiplier>
          <offset>0</offset>
          <reference>0</reference>
        </mimic>
        <limit>
          <lower>0.00043459999999999999</lower>
          <upper>1.2464</upper>
          <effort>100</effort>
          <velocity>100</velocity>
        </limit>
        <dynamics>
          <spring_reference>0</spring_reference>
          <spring_stiffness>0</spring_stiffness>
        </dynamics>
      </axis>
    </joint>
    <link name='lowerleg_virtual'>
      <pose relative_to='mimic_lowerleg'>0 0 0 0 0 0</pose>
      <inertial>
        <pose>0.14999999999999999 -0.14000000000000001 -0.0050000000000000001 0 0 0</pose>
        <mass>0.001</mass>
        <inertia>
          <ixx>9.9999999999999995e-07</ixx>
          <ixy>0</ixy>
          <ixz>0</ixz>
          <iyy>9.9999999999999995e-07</iyy>
          <iyz>0</iyz>
          <izz>9.9999999999999995e-07</izz>
        </inertia>
      </inertial>
    </link>
    <joint name='Rigid 14' type='revolute'>
      <pose relative_to='lowerleg_virtual'>-0.11952 0.010999999999999999 0 0 0 0</pose>
      <parent>lowerleg_virtual</parent>
      <child>lowerleg_1</child>
      <axis>
        <xyz>0 0 1</xyz>
        <limit>
          <lower>0.00043459999999999999</lower>
          <upper>1.2464</upper>
          <effort>100</effort>
          <velocity>100</velocity>
        </limit>
        <dynamics>
          <spring_reference>0</spring_reference>
          <spring_stiffness>0</spring_stiffness>
        </dynamics>
      </axis>
    </joint>
    <link name='lowerleg_1'>
      <pose relative_to='Rigid 14'>0 0 0 0 0 0</pose>
      <inertial>
        <pose>-0.00034015470186466302 -0.1100407436208491 0.006247365424084262 0 0 0</pose>
        <mass>0.045952402766917019</mass>
        <inertia>
          <ixx>0.00010223767438552581</ixx>
          <ixy>1.7798738718456909e-06</ixy>
          <ixz>-6.0988829695134905e-11</ixz>
          <iyy>3.0078749101290301e-06</iyy>
          <iyz>6.0402528028944118e-09</iyz>
          <izz>0.0001022455483509175</izz>
        </inertia>
      </inertial>
      <collision name='lowerleg_1_collision'>
        <pose>0.14999999999999999 -0.14000000000000001 -0.0050000000000000001 0 0 0</pose>
        <geometry>
          <mesh>
            <scale>0.001 0.001 0.001</scale>
            <uri>file:///home/houndsito/leg1_ws/install/leg1_description/share/leg1_description/meshes/lowerleg_1.stl</uri>
          </mesh>
        </geometry>
        <surface>
          <contact>
            <ode/>
          </contact>
          <friction>
            <ode>
              <mu>0.20000000000000001</mu>
              <mu2>0.20000000000000001</mu2>
            </ode>
          </friction>
        </surface>
      </collision>
      <collision name='lowerleg_1_fixed_joint_lump__sphere_1_collision_1'>
        <pose>0.14749999999999999 -0.26550000000000001 0.003750000000000002 0 0 0</pose>
        <geometry>
          <mesh>
            <scale>0.001 0.001 0.001</scale>
            <uri>file:///home/houndsito/leg1_ws/install/leg1_description/share/leg1_description/meshes/sphere_1.stl</uri>
          </mesh>
        </geometry>
        <surface>
          <contact>
            <ode/>
          </contact>
          <friction>
            <ode>
              <mu>0.20000000000000001</mu>
              <mu2>0.20000000000000001</mu2>
            </ode>
          </friction>
        </surface>
      </collision>
      <visual name='lowerleg_1_visual'>
        <pose>0.14999999999999999 -0.14000000000000001 -0.0050000000000000001 0 0 0</pose>
        <geometry>
          <mesh>
            <scale>0.001 0.001 0.001</scale>
            <uri>file:///home/houndsito/leg1_ws/install/leg1_description/share/leg1_description/meshes/lowerleg_1.stl</uri>
          </mesh>
        </geometry>
        <material>
          <script>
            <name>Gazebo/Silver</name>
            <uri>file://media/materials/scripts/gazebo.material</uri>
          </script>
          <diffuse>0.875 0.875 0.875 1</diffuse>
          <ambient>0.875 0.875 0.875 1</ambient>
        </material>
      </visual>
      <visual name='lowerleg_1_fixed_joint_lump__sphere_1_visual_1'>
        <pose>0.14749999999999999 -0.26550000000000001 0.003750000000000002 0 0 0</pose>
        <geometry>
          <mesh>
            <scale>0.001 0.001 0.001</scale>
            <uri>file:///home/houndsito/leg1_ws/install/leg1_description/share/leg1_description/meshes/sphere_1.stl</uri>
          </mesh>
        </geometry>
        <material>
          <script>
            <name>Gazebo/Silver</name>
            <uri>file://media/materials/scripts/gazebo.material</uri>
          </script>
          <diffuse>0.875 0.875 0.875 1</diffuse>
          <ambient>0.875 0.875 0.875 1</ambient>
        </material>
      </visual>
      <self_collide>true</self_collide>
      <self_collide>true</self_collide>
      <self_collide>true</self_collide>
    </link>
    <joint name='Revolute 9' type='revolute'>
      <pose relative_to='base_link'>-0.03048 0.12926299999999999 0.0050000000000000001 0 0 0</pose>
      <parent>base_link</parent>
      <child>driveleg_1</child>
      <axis>
        <xyz>0 0 -1</xyz>
        <limit>
          <lower>-0.54105199999999998</lower>
          <upper>0.48869200000000002</upper>
          <effort>100</effort>
          <velocity>100</velocity>
        </limit>
        <dynamics>
          <spring_reference>0</spring_reference>
          <spring_stiffness>0</spring_stiffness>
        </dynamics>
      </axis>
    </joint>
    <link name='driveleg_1'>
      <pose relative_to='Revolute 9'>0 0 0 0 0 0</pose>
      <inertial>
        <pose>-0.059768651064305352 0.0054291149433868258 0.0048959302189582722 0 0 0</pose>
        <mass>0.02344626581651121</mass>
        <inertia>
          <ixx>2.5000000000000002e-06</ixx>
          <ixy>0</ixy>
          <ixz>0</ixz>
          <iyy>5.0000000000000002e-05</iyy>
          <iyz>0</iyz>
          <izz>5.1999999999999997e-05</izz>
        </inertia>
      </inertial>
      <collision name='driveleg_1_collision'>
        <pose>0.03048 -0.12926299999999999 -0.0050000000000000001 0 0 0</pose>
        <geometry>
          <mesh>
            <scale>0.001 0.001 0.001</scale>
            <uri>file:///home/houndsito/leg1_ws/install/leg1_description/share/leg1_description/meshes/driveleg_1.stl</uri>
          </mesh>
        </geometry>
        <surface>
          <contact>
            <ode/>
          </contact>
          <friction>
            <ode>
              <mu>0.20000000000000001</mu>
              <mu2>0.20000000000000001</mu2>
            </ode>
          </friction>
        </surface>
      </collision>
      <visual name='driveleg_1_visual'>
        <pose>0.03048 -0.12926299999999999 -0.0050000000000000001 0 0 0</pose>
        <geometry>
          <mesh>
            <scale>0.001 0.001 0.001</scale>
            <uri>file:///home/houndsito/leg1_ws/install/leg1_description/share/leg1_description/meshes/driveleg_1.stl</uri>
          </mesh>
        </geometry>
        <material>
          <script>
            <name>Gazebo/Silver</name>
            <uri>file://media/materials/scripts/gazebo.material</uri>
          </script>
          <diffuse>0.875 0.875 0.875 1</diffuse>
          <ambient>0.875 0.875 0.875 1</ambient>
        </material>
      </visual>
      <self_collide>true</self_collide>
    </link>
    <joint name='Rigid 14' type='revolute'>
      <pose relative_to='lowerleg_virtual'>-0.11952 0.010999999999999999 0 0 0 0</pose>
      <parent>lowerleg_virtual</parent>
      <child>lowerleg_1</child>
      <axis>
        <xyz>0 0 1</xyz>
        <limit>
          <lower>0.00043459999999999999</lower>
          <upper>1.2464</upper>
          <effort>100</effort>
          <velocity>100</velocity>
        </limit>
        <dynamics>
          <spring_reference>0</spring_reference>
          <spring_stiffness>0</spring_stiffness>
        </dynamics>
      </axis>
    </joint>
    <link name='lowerleg_1'>
      <pose relative_to='Rigid 14'>0 0 0 0 0 0</pose>
      <inertial>
        <pose>-0.00034015470186466302 -0.1100407436208491 0.006247365424084262 0 0 0</pose>
        <mass>0.045952402766917019</mass>
        <inertia>
          <ixx>0.00010223767438552581</ixx>
          <ixy>1.7798738718456909e-06</ixy>
          <ixz>-6.0988829695134905e-11</ixz>
          <iyy>3.0078749101290301e-06</iyy>
          <iyz>6.0402528028944118e-09</iyz>
          <izz>0.0001022455483509175</izz>
        </inertia>
      </inertial>
      <collision name='lowerleg_1_collision'>
        <pose>0.14999999999999999 -0.14000000000000001 -0.0050000000000000001 0 0 0</pose>
        <geometry>
          <mesh>
            <scale>0.001 0.001 0.001</scale>
            <uri>file:///home/houndsito/leg1_ws/install/leg1_description/share/leg1_description/meshes/lowerleg_1.stl</uri>
          </mesh>
        </geometry>
        <surface>
          <contact>
            <ode/>
          </contact>
          <friction>
            <ode>
              <mu>0.20000000000000001</mu>
              <mu2>0.20000000000000001</mu2>
            </ode>
          </friction>
        </surface>
      </collision>
      <collision name='lowerleg_1_fixed_joint_lump__sphere_1_collision_1'>
        <pose>0.14749999999999999 -0.26550000000000001 0.003750000000000002 0 0 0</pose>
        <geometry>
          <mesh>
            <scale>0.001 0.001 0.001</scale>
            <uri>file:///home/houndsito/leg1_ws/install/leg1_description/share/leg1_description/meshes/sphere_1.stl</uri>
          </mesh>
        </geometry>
        <surface>
          <contact>
            <ode/>
          </contact>
          <friction>
            <ode>
              <mu>0.20000000000000001</mu>
              <mu2>0.20000000000000001</mu2>
            </ode>
          </friction>
        </surface>
      </collision>
      <visual name='lowerleg_1_visual'>
        <pose>0.14999999999999999 -0.14000000000000001 -0.0050000000000000001 0 0 0</pose>
        <geometry>
          <mesh>
            <scale>0.001 0.001 0.001</scale>
            <uri>file:///home/houndsito/leg1_ws/install/leg1_description/share/leg1_description/meshes/lowerleg_1.stl</uri>
          </mesh>
        </geometry>
        <material>
          <script>
            <name>Gazebo/Silver</name>
            <uri>file://media/materials/scripts/gazebo.material</uri>
          </script>
          <diffuse>0.875 0.875 0.875 1</diffuse>
          <ambient>0.875 0.875 0.875 1</ambient>
        </material>
      </visual>
      <visual name='lowerleg_1_fixed_joint_lump__sphere_1_visual_1'>
        <pose>0.14749999999999999 -0.26550000000000001 0.003750000000000002 0 0 0</pose>
        <geometry>
          <mesh>
            <scale>0.001 0.001 0.001</scale>
            <uri>file:///home/houndsito/leg1_ws/install/leg1_description/share/leg1_description/meshes/sphere_1.stl</uri>
          </mesh>
        </geometry>
        <material>
          <script>
            <name>Gazebo/Silver</name>
            <uri>file://media/materials/scripts/gazebo.material</uri>
          </script>
          <diffuse>0.875 0.875 0.875 1</diffuse>
          <ambient>0.875 0.875 0.875 1</ambient>
        </material>
      </visual>
      <self_collide>true</self_collide>
      <self_collide>true</self_collide>
      <self_collide>true</self_collide>
    </link>
    <plugin name='control' filename='libgazebo_ros_control.so'/>
    <frame name='Rigid 13' attached_to='lowerleg_1'>
      <pose>-0.0025000000000000001 -0.1255 0.0087500000000000008 0 0 0</pose>
    </frame>
    <frame name='sphere_1' attached_to='Rigid 13'>
      <pose>0 0 0 0 0 0</pose>
    </frame>
    <frame name='Rigid 13' attached_to='lowerleg_1'>
      <pose>-0.0025000000000000001 -0.1255 0.0087500000000000008 0 0 0</pose>
    </frame>
    <frame name='sphere_1' attached_to='Rigid 13'>
      <pose>0 0 0 0 0 0</pose>
    </frame>
  </model>
</sdf>
