<?xml version="1.0" ?>
<robot name="leg1" xmlns:xacro="http://www.ros.org/wiki/xacro">

<xacro:include filename="$(find leg1_description)/urdf/materials.xacro" />
<xacro:include filename="$(find leg1_description)/urdf/leg1.trans" />
<xacro:include filename="$(find leg1_description)/urdf/leg1.gazebo" />
<link name="base_link">
  <inertial>
    <origin xyz="-0.0005585685606280078 0.12100156940500095 0.0024999999999999974" rpy="0 0 0"/>
    <mass value="0.01789284440704088"/>
    <inertia ixx="6e-06" iyy="5e-06" izz="1e-05" ixy="-0.0" iyz="-0.0" ixz="0.0"/>
  </inertial>
  <visual>
    <origin xyz="0 0 0" rpy="0 0 0"/>
    <geometry>
      <mesh filename="file://$(find leg1_description)/meshes/base_link.stl" scale="0.001 0.001 0.001"/>
    </geometry>
    <material name="silver"/>
  </visual>
  <collision>
    <origin xyz="0 0 0" rpy="0 0 0"/>
    <geometry>
      <mesh filename="file://$(find leg1_description)/meshes/base_link.stl" scale="0.001 0.001 0.001"/>
    </geometry>
  </collision>
</link>

<link name="upperleg_1">
  <inertial>
    <origin xyz="-0.07539116548053411 0.0 0.004899999999999997" rpy="0 0 0"/>
    <mass value="0.03949880401995079"/>
    <inertia ixx="2e-06" iyy="9.1e-05" izz="9.3e-05" ixy="0.0" iyz="0.0" ixz="-0.0"/>
  </inertial>
  <visual>
    <origin xyz="0.0 -0.09 -0.005" rpy="0 0 0"/>
    <geometry>
      <mesh filename="file://$(find leg1_description)/meshes/upperleg_1.stl" scale="0.001 0.001 0.001"/>
    </geometry>
    <material name="silver"/>
  </visual>
  <collision>
    <origin xyz="0.0 -0.09 -0.005" rpy="0 0 0"/>
    <geometry>
      <mesh filename="file://$(find leg1_description)/meshes/upperleg_1.stl" scale="0.001 0.001 0.001"/>
    </geometry>
  </collision>
</link>

<link name="driveleg_1">
  <inertial>
    <origin xyz="-0.05976865106430535 0.005429114943386826 0.004895930218958272" rpy="0 0 0"/>
    <mass value="0.023446265816511214"/>
    <inertia ixx="1e-06" iyy="4.5e-05" izz="4.6e-05" ixy="4e-06" iyz="0.0" ixz="-0.0"/>
  </inertial>
  <visual>
    <origin xyz="0.03048 -0.129263 -0.005" rpy="0 0 0"/>
    <geometry>
      <mesh filename="file://$(find leg1_description)/meshes/driveleg_1.stl" scale="0.001 0.001 0.001"/>
    </geometry>
    <material name="silver"/>
  </visual>
  <collision>
    <origin xyz="0.03048 -0.129263 -0.005" rpy="0 0 0"/>
    <geometry>
      <mesh filename="file://$(find leg1_description)/meshes/driveleg_1.stl" scale="0.001 0.001 0.001"/>
    </geometry>
  </collision>
</link>

<link name="lowerleg_1">
  <inertial>
    <origin xyz="-0.0008439272273708387 -0.060147780853207225 0.006243463622114645" rpy="0 0 0"/>
    <mass value="0.018521660836523925"/>
    <inertia ixx="2.3e-05" iyy="1e-06" izz="2.3e-05" ixy="1e-06" iyz="-0.0" ixz="0.0"/>
  </inertial>
  <visual>
    <origin xyz="0.15 -0.14 -0.005" rpy="0 0 0"/>
    <geometry>
      <mesh filename="file://$(find leg1_description)/meshes/lowerleg_1.stl" scale="0.001 0.001 0.001"/>
    </geometry>
    <material name="silver"/>
  </visual>
  <collision>
    <origin xyz="0.15 -0.14 -0.005" rpy="0 0 0"/>
    <geometry>
      <mesh filename="file://$(find leg1_description)/meshes/lowerleg_1.stl" scale="0.001 0.001 0.001"/>
    </geometry>
  </collision>
</link>

<link name="sphere_1">
  <inertial>
    <origin xyz="0.002500000292114779 -0.01822924307363568 -0.0025000000189316137" rpy="0 0 0"/>
    <mass value="0.013715370965196549"/>
    <inertia ixx="1e-06" iyy="1e-06" izz="1e-06" ixy="-0.0" iyz="0.0" ixz="0.0"/>
  </inertial>
  <visual>
    <origin xyz="0.1525 -0.0145 -0.01375" rpy="0 0 0"/>
    <geometry>
      <mesh filename="file://$(find leg1_description)/meshes/sphere_1.stl" scale="0.001 0.001 0.001"/>
    </geometry>
    <material name="silver"/>
  </visual>
  <collision>
    <origin xyz="0.1525 -0.0145 -0.01375" rpy="0 0 0"/>
    <geometry>
      <mesh filename="file://$(find leg1_description)/meshes/sphere_1.stl" scale="0.001 0.001 0.001"/>
    </geometry>
  </collision>
</link>

<link name="lowerleg_1">
  <inertial>
    <origin xyz="-0.0008439272273708387 -0.010147780853207208 0.006243463622114645" rpy="0 0 0"/>
    <mass value="0.018521660836523925"/>
    <inertia ixx="2.3e-05" iyy="1e-06" izz="2.3e-05" ixy="1e-06" iyz="-0.0" ixz="0.0"/>
  </inertial>
  <visual>
    <origin xyz="0.15 -0.09 -0.005" rpy="0 0 0"/>
    <geometry>
      <mesh filename="file://$(find leg1_description)/meshes/lowerleg_1.stl" scale="0.001 0.001 0.001"/>
    </geometry>
    <material name="silver"/>
  </visual>
  <collision>
    <origin xyz="0.15 -0.09 -0.005" rpy="0 0 0"/>
    <geometry>
      <mesh filename="file://$(find leg1_description)/meshes/lowerleg_1.stl" scale="0.001 0.001 0.001"/>
    </geometry>
  </collision>
</link>

<joint name="Revolute 8" type="revolute">
  <origin xyz="0.0 0.09 0.005" rpy="0 0 0"/>
  <parent link="base_link"/>
  <child link="upperleg_1"/>
  <axis xyz="0.0 0.0 1.0"/>
  <limit upper="0.471239" lower="-0.331613" effort="100" velocity="100"/>
</joint>

<joint name="Revolute 9" type="revolute">
  <origin xyz="-0.03048 0.129263 0.005" rpy="0 0 0"/>
  <parent link="base_link"/>
  <child link="driveleg_1"/>
  <axis xyz="0.0 0.0 -1.0"/>
  <limit upper="0.488692" lower="-0.541052" effort="100" velocity="100"/>
</joint>

<joint name="Revolute 10" type="revolute">
  <origin xyz="-0.11952 -0.039263 0.0" rpy="0 0 0"/>
  <parent link="driveleg_1"/>
  <child link="lowerleg_1"/>
  <axis xyz="0.0 0.0 1.0"/>
  <limit upper="1.134464" lower="0.244346" effort="100" velocity="100"/>
</joint>

<joint name="Rigid 13" type="fixed">
  <origin xyz="-0.0025 -0.0755 0.00875" rpy="0 0 0"/>
  <parent link="lowerleg_1"/>
  <child link="sphere_1"/>
</joint>

<joint name="Revolute 14" type="revolute">
  <origin xyz="-0.15 0.0 0.0" rpy="0 0 0"/>
  <parent link="upperleg_1"/>
  <child link="lowerleg_1"/>
  <axis xyz="0.0 0.0 1.0"/>
  <limit upper="0.191986" lower="-0.506145" effort="100" velocity="100"/>
</joint>

</robot>
